Workbook

Sheet Disponibilidad 26-2
B2: FORMATO DE DISPONIBILIDAD | L2: FORMATO DE DISPONIBILIDAD
G3: Ciclo:26-2 | Q3: Ciclo:26-2
B4: Nombre: | C4: Bruce David Marron | L4: Nombre: | M4: =C4 -> Bruce David Marron
B5: Profesión: | C5: Docente / Profe | L5: Profesión: | M5: =C5 -> Docente / Profe
B6: Tel. Casa: | E6: Tel. Celular: | F6: 55 4190 9628 | L6: Tel. Casa: | M6: =C6 -> 0 | O6: Tel. Celular: | P6: =F6 -> 55 4190 9628
B7: E-mail: | C7: marron.bruce.mx@gmail.com | L7: E-mail: | M7: =C7 -> marron.bruce.mx@gmail.com
B9: Capture 1, 2 o X dentro del área de disponibilidad
A10: 1 | B10: Disponibilidad para la Dirección de Innovación en Medios y Contenidos Digitales
A11: 2 | B11: Disponibilidad para la Dirección de Idiomas e Internacionalización
A12: X | B12: Disponibilidad para ambas Direcciones
B14: Horario | C14: Lunes | D14: Martes | E14: Miercoles | F14: Jueves | G14: Viernes | L14: Horario | M14: Lunes | N14: Martes | O14: Miercoles | P14: Jueves | Q14: Viernes
A15: MATUTINO | B15: 07:00 -08:00 | K15: MATUTINO | L15: 07:00 -08:00
B16: 08:00 - 09:00 | L16: 08:00 - 09:00
B17: 09:00 - 10:00 | L17: 09:00 - 10:00
B18: 10:00 - 11:00 | L18: 10:00 - 11:00
B19: 11:00 - 12:00 | L19: 11:00 - 12:00
B20: 12:00 -13:00 | D20: 2 | E20: 2 | F20: 2 | L20: 12:00 -13:00
B21: 13:00 - 14:00 | D21: 2 | E21: 2 | F21: 2 | L21: 13:00 - 14:00
B22: 14:00 - 15:00 | D22: 2 | E22: 2 | F22: 2 | L22: 14:00 - 15:00
A23: VESPERTINO | B23: 15:00 - 16:00 | D23: 2 | E23: 2 | F23: 2 | K23: VESPERTINO | L23: 15:00 - 16:00
B24: 16:00 - 17:00 | D24: 2 | E24: 2 | F24: 2 | L24: 16:00 - 17:00
B25: 17:00 - 18:00 | D25: 2 | E25: 2 | F25: 2 | L25: 17:00 - 18:00
B26: 18:00 - 19:00 | D26: 2 | E26: 2 | F26: 2 | L26: 18:00 - 19:00
B27: 19:00 -20:00 | D27: 2 | E27: 2 | F27: 2 | L27: 19:00 -20:00
B28: 20:00 -21:00 | D28: 2 | E28: 2 | F28: 2 | L28: 20:00 -21:00
B29: 21:00 - 22:00 | L29: 21:00 - 22:00
B31: MATERIAS DE SU INTERÉS (no hay límite en el número de materias para solicitar)
B32: Selecciona una materia de lista desplegable en la zona sombreada,
B33: y captura los años de experiencia laboral y docente | L33: ASIGNACIÓN DE MATERIAS
B35: Cuatri. / Lic. / Grupo A B C / Materia / Horas | F35: Años Exp. Laboral | G35: Años Exp. Docente | H35: Software Necesario | L35: Clave | M35: Materia asignada | P35: Horas | Q35: Horas Asignadas | R35: Horas Faltantes
A36: =IFERROR(VLOOKUP(B36,Materias_Dispo_26_2!$C$3:$I$267,6,FALSE()),"") -> INT1044 | B36: 10. INT Inglés X (4) | F36: 15 | G36: 10’+ | H36: Word processor (google docs, Word, Libre Office, LaTex) | K36: =IF(L36<>"",K35+1,"") | L36: =IFERROR(VLOOKUP(M36,Materias_Dispo_26_2!$C$3:$I$267,6,FALSE()),"") | P36: =IFERROR(VLOOKUP(M36,Materias_Dispo_26_2!C3:I267,7,FALSE()),"") | Q36: =IF(L36="","",COUNTIF($M$15:$R$29,L36)) | R36: =IFERROR(P36-Q36,"")
A37: =IFERROR(VLOOKUP(B37,Materias_Dispo_26_2!$C$3:$I$267,6,FALSE()),"") -> INT0939 | B37: 9. INT Inglés IX (4) | F37: 15 | G37: 10’+ | H37: Word processor (google docs, Word, Libre Office, LaTex) | K37: =IF(L37<>"",K36+1,"") | L37: =IFERROR(VLOOKUP(M37,Materias_Dispo_26_2!$C$3:$I$267,6,FALSE()),"") | P37: =IFERROR(VLOOKUP(M37,Materias_Dispo_26_2!C4:I268,7,FALSE()),"") | Q37: =IF(L37="","",COUNTIF($M$15:$R$29,L37)) | R37: =IFERROR(P37-Q37,"")
A38: =IFERROR(VLOOKUP(B38,Materias_Dispo_26_2!$C$3:$I$267,6,FALSE()),"") | K38: =IF(L38<>"",K37+1,"") | L38: =IFERROR(VLOOKUP(M38,Materias_Dispo_26_2!$C$3:$I$267,6,FALSE()),"") | P38: =IFERROR(VLOOKUP(M38,Materias_Dispo_26_2!C5:I269,7,FALSE()),"") | Q38: =IF(L38="","",COUNTIF($M$15:$R$29,L38)) | R38: =IFERROR(P38-Q38,"")
A39: =IFERROR(VLOOKUP(B39,Materias_Dispo_26_2!$C$3:$I$267,6,FALSE()),"") | K39: =IF(L39<>"",K38+1,"") | L39: =IFERROR(VLOOKUP(M39,Materias_Dispo_26_2!$C$3:$I$267,6,FALSE()),"") | P39: =IFERROR(VLOOKUP(M39,Materias_Dispo_26_2!C6:I270,7,FALSE()),"") | Q39: =IF(L39="","",COUNTIF($M$15:$R$29,L39)) | R39: =IFERROR(P39-Q39,"")
A40: =IFERROR(VLOOKUP(B40,Materias_Dispo_26_2!$C$3:$I$267,6,FALSE()),"") | K40: =IF(L40<>"",K39+1,"") | L40: =IFERROR(VLOOKUP(M40,Materias_Dispo_26_2!$C$3:$I$267,6,FALSE()),"") | P40: =IFERROR(VLOOKUP(M40,Materias_Dispo_26_2!C7:I271,7,FALSE()),"") | Q40: =IF(L40="","",COUNTIF($M$15:$R$29,L40)) | R40: =IFERROR(P40-Q40,"")
A41: =IFERROR(VLOOKUP(B41,Materias_Dispo_26_2!$C$3:$I$267,6,FALSE()),"") | K41: =IF(L41<>"",K40+1,"") | L41: =IFERROR(VLOOKUP(M41,Materias_Dispo_26_2!$C$3:$I$267,6,FALSE()),"") | P41: =IFERROR(VLOOKUP(M41,Materias_Dispo_26_2!C8:I272,7,FALSE()),"") | Q41: =IF(L41="","",COUNTIF($M$15:$R$29,L41)) | R41: =IFERROR(P41-Q41,"")
A42: =IFERROR(VLOOKUP(B42,Materias_Dispo_26_2!$C$3:$I$267,6,FALSE()),"") | K42: =IF(L42<>"",K41+1,"") | L42: =IFERROR(VLOOKUP(M42,Materias_Dispo_26_2!$C$3:$I$267,6,FALSE()),"") | P42: =IFERROR(VLOOKUP(M42,Materias_Dispo_26_2!C9:I273,7,FALSE()),"") | Q42: =IF(L42="","",COUNTIF($M$15:$R$29,L42)) | R42: =IFERROR(P42-Q42,"")
A43: =IFERROR(VLOOKUP(B43,Materias_Dispo_26_2!$C$3:$I$267,6,FALSE()),"") | K43: =IF(L43<>"",K42+1,"") | L43: =IFERROR(VLOOKUP(M43,Materias_Dispo_26_2!$C$3:$I$267,6,FALSE()),"") | P43: =IFERROR(VLOOKUP(M43,Materias_Dispo_26_2!C10:I274,7,FALSE()),"") | Q43: =IF(L43="","",COUNTIF($M$15:$R$29,L43)) | R43: =IFERROR(P43-Q43,"")
A44: =IFERROR(VLOOKUP(B44,Materias_Dispo_26_2!$C$3:$I$267,6,FALSE()),"") | K44: =IF(L44<>"",K43+1,"") | L44: =IFERROR(VLOOKUP(M44,Materias_Dispo_26_2!$C$3:$I$267,6,FALSE()),"") | P44: =IFERROR(VLOOKUP(M44,Materias_Dispo_26_2!C11:I275,7,FALSE()),"") | Q44: =IF(L44="","",COUNTIF($M$15:$R$29,L44)) | R44: =IFERROR(P44-Q44,"")
A45: =IFERROR(VLOOKUP(B45,Materias_Dispo_26_2!$C$3:$I$267,6,FALSE()),"") | K45: =IF(L45<>"",K44+1,"") | L45: =IFERROR(VLOOKUP(M45,Materias_Dispo_26_2!$C$3:$I$267,6,FALSE()),"") | P45: =IFERROR(VLOOKUP(M45,Materias_Dispo_26_2!C12:I276,7,FALSE()),"") | Q45: =IF(L45="","",COUNTIF($M$15:$R$29,L45)) | R45: =IFERROR(P45-Q45,"")
...

Sheet LabCompSoft
A1: No. | B1: Laboratorio | D1: No. | E1: SOFTWARE
A2: 1 | B2: MAC o PC es lo mismo | D2: 1 | E2: 7-Zip 21.07 (x64)
A3: 2 | B3: MAC No importa la sala | D3: 2 | E3: Adobe Acrobat (64 bits)
A4: 3 | B4: PC No importa la sala | D4: 3 | E4: Adobe After Effects 2025
A5: 4 | B5: MAC 01 | D5: 4 | E5: Adobe Animate 2025
A6: 5 | B6: MAC 02 | D6: 5 | E6: Adobe Audition 2025
A7: 6 | B7: MAC 03 | D7: 6 | E7: Adobe Creative Cloud
A8: 7 | B8: PC 04 | D8: 7 | E8: Adobe Illustrator 2025
A9: 8 | B9: PC 05 | D9: 8 | E9: Adobe InDesign 2025
A10: 9 | B10: PC 06 | D10: 9 | E10: Adobe Lightroom
A11: 10 | B11: PC 07 | D11: 10 | E11: Adobe Media Encoder 2025
A12: 11 | B12: Ninguno | D12: 11 | E12: Adobe Photoshop 2025
D13: 12 | E13: Adobe Premiere Pro 2025
D14: 13 | E14: Adobe Substance 3D for Maya 2025
D15: 14 | E15: Adobe Substance 3D Painter
D16: 15 | E16: Audacity 3.3.1
D17: 16 | E17: Autodesk AutoCAD 2026 – Español
D18: 17 | E18: Autodesk Maya 2025
D19: 18 | E19: Autodesk Mudbox 2025
D20: 19 | E20: Blender
D21: 20 | E21: CapCut
D22: 21 | E22: CCleaner
D23: 22 | E23: Cinema 4D 2025
D24: 23 | E24: Epic Games
... D44: 43 | E44: XAMMP

Sheet Materias_Dispo_26_2
A2: No. | B2: Lic | D2: Id_Lic | E2: Cuatrimestre | F2: No_Materia | G2: Materia | H2: Clave_Materia | I2: Horas_Tot
A3: 1 | B3: 1 | C3: =_xlfn.CONCAT(E3,". ",D3," ",G3," (",I3,")") -> 1. ACT Álgebra Superior I (4) | D3: ACT | E3: 1 | F3: 1 | G3: Álgebra Superior I | H3: LAE0101 | I3: 4
A4: 2 | B4: 1 | C4: =_xlfn.CONCAT(E4,". ",D4," ",G4," (",I4,")") -> 1. ACT Introducción a la Programación (4) | D4: ACT | E4: 1 | F4: 2 | G4: Introducción a la Programación | H4: LAE0102 | I4: 4
A5: 3 | B5: 1 | C5: =_xlfn.CONCAT(E5,". ",D5," ",G5," (",I5,")") -> 1. ACT Cálculo Diferencial e Intregal I (6) | D5: ACT | E5: 1 | F5: 3 | G5: Cálculo Diferencial e Intregal I | H5: LAE0103 | I5: 6
A6: 4 | B6: 1 | C6: =_xlfn.CONCAT(E6,". ",D6," ",G6," (",I6,")") -> 1. ACT Geometría Analítica (4) | D6: ACT | E6: 1 | F6: 4 | G6: Geometría Analítica | H6: LAE0104 | I6: 4
A7: 5 | B7: 1 | C7: =_xlfn.CONCAT(E7,". ",D7," ",G7," (",I7,")") -> 1. ACT Teoría Financiera (4) | D7: ACT | E7: 1 | F7: 5 | G7: Teoría Financiera | H7: LAE0105 | I7: 4
A8: 6 | B8: 1 | C8: =_xlfn.CONCAT(E8,". ",D8," ",G8," (",I8,")") -> 2. ACT Álgebra Superior II (4) | D8: ACT | E8: 2 | F8: 1 | G8: Álgebra Superior II | H8: LAE0206 | I8: 4
A9: 7 | B9: 1 | C9: =_xlfn.CONCAT(E9,". ",D9," ",G9," (",I9,")") -> 2. ACT Programación Orientada a Objetos (POO) (4) | D9: ACT | E9: 2 | F9: 2 | G9: Programación Orientada a Objetos (POO) | H9: LAE0207 | I9: 4
A10: 8 | B10: 1 | C10: =_xlfn.CONCAT(E10,". ",D10," ",G10," (",I10,")") -> 2. ACT Cálculo Diferencial e Integral II (4) | D10: ACT | E10: 2 | F10: 3 | G10: Cálculo Diferencial e Integral II | H10: LAE0208 | I10: 4
A11: 9 | B11: 1 | C11: =_xlfn.CONCAT(E11,". ",D11," ",G11," (",I11,")") -> 2. ACT Teoría de Seguros y Fianzas (3) | D11: ACT | E11: 2 | F11: 4 | G11: Teoría de Seguros y Fianzas | H11: LAE0209 | I11: 3
A12: 10 | B12: 1 | C12: =_xlfn.CONCAT(E12,". ",D12," ",G12," (",I12,")") -> 2. ACT Matemáticas Financieras Avanzadas (4) | D12: ACT | E12: 2 | F12: 5 | G12: Matemáticas Financieras Avanzadas | H12: LAE0210 | I12: 4
A13: 11 | B13: 1 | C13: =_xlfn.CONCAT(E13,". ",D13," ",G13," (",I13,")") -> 5. ACT Economía (5) | D13: ACT | E13: 5 | F13: 1 | G13: Economía | H13: LAE0521 | I13: 5
A14: 12 | B14: 1 | C14: =_xlfn.CONCAT(E14,". ",D14," ",G14," (",I14,")") -> 5. ACT Análisis Estadístico Paramétrico (5) | D14: ACT | E14: 5 | F14: 2 | G14: Análisis Estadístico Paramétrico | H14: LAE0522 | I14: 5
... A267: 265 | B267: 10 | C267: =_xlfn.CONCAT(E267,". ",D267," ",G267," (",I267,")") -> 6. MRP Diseño Web y Mercadotecnia Digital (6) | D267: MRP | E267: 6 | F267: 5 | G267: Diseño Web y Mercadotecnia Digital | H267: MRP0630 | I267: 6
